<?xml version='1.0'?>
<sdf version='1.4'>
	<model name="Fake_Shopper">
		<static>false</static>
		
		<!--********  APRIL TAG ********-->
		<link name="april_tag">
			<pose>0 -0.130 0.875 0 0 0</pose>
			<gravity>1</gravity>
			<inertial>
				<mass>1</mass>
				<pose>0 0.130 -0.825 0 0 0</pose>
				<inertia>
					<ixx>0.5</ixx>
					<iyy>1.0</iyy>
					<izz>0.1</izz>
				</inertia>
			</inertial>
			<visual name='april_tag_visual'>
				<geometry>
					<box>
						<size>0.3 0.01 0.3 </size>
					</box>
				</geometry>
				<material>
					<script>
						<uri>model://Fake_Shopper/scripts/</uri>
						<uri>model:://Fake_Shopper/textures</uri>
						<name>AprilTag/Diffuse</name>
					</script>
					<lighting>0</lighting>
				</material>
			</visual>

			<collision name='april_tag_collision'>
				<geometry>
					<box>
						<size>0.3 0.01 0.3 </size>
					</box>
				</geometry>
                                <material>
					<script>
						<uri>model://Fake_Shopper/scripts/</uri>
						<uri>model:://Fake_Shopper/textures</uri>
						<name>AprilTag/Diffuse</name>
					</script>
					<lighting>0</lighting>
				</material>
			</collision>
		</link>

		<!--********  BODY ********-->
		<link name='body'>
			<pose>0 0 0.875 0 0 0</pose>
			<inertial>
				<mass>80</mass>
				<pose>0 0 -0.825 0 0 0</pose>
				<inertia>
					<ixx>0.5</ixx>
					<iyy>1.0</iyy>
					<izz>0.1</izz>
				</inertia>
			</inertial>
			<collision name='body_collision'>
				<geometry>
					<box>
						<size>0.5 0.25 1.65</size>
					</box>
				</geometry>
			</collision>

			<visual name='body_visual'>
				<geometry>
					<box>
						<size>0.5 0.25 1.65</size>
					</box>
				</geometry>
			</visual>
			
			<!--********  CASTER WHEEL ********-->
			<collision name='caster_collision'>
				<pose>0 0.075 -0.85 0 0 0</pose>
				<geometry>
					<sphere>
						<radius>0.025</radius>
					</sphere>
				</geometry>

				<surface>
					<friction>
						<ode>
							<mu>0</mu>
							<mu2>0</mu2>
							<slip1>1.0</slip1>
							<slip2>1.0</slip2>
						</ode>
					</friction>
				</surface>
			</collision>

			<visual name='caster_visual'>
				<pose>0 0.075 -0.85 0 0 0</pose>
				<geometry>
					<sphere>
						<radius>0.025</radius>
					</sphere>
				</geometry>
			</visual>
		</link>
		
		<!--********  LEFT WHEEL ********-->
		<link name="left_wheel">
			<pose>-0.275 -0.075 0.05 0 1.5707 6.283</pose>
			<inertial>
				<mass>1</mass>
				<pose>0 0 0.05 0 0 0</pose>
				<inertia>
					<ixx>0.5</ixx>
					<iyy>1.0</iyy>
					<izz>0.1</izz>
				</inertia>
			</inertial>
			<collision name="left_wheel_collision">
				<geometry>
					<cylinder>
						<radius>0.05</radius>
						<length>0.05</length>
					</cylinder>
				</geometry>
			</collision>
			<visual name="left_wheel_visual">
				<geometry>
					<cylinder>
						<radius>0.05</radius>
						<length>0.05</length>
					</cylinder>
				</geometry>
			</visual>
		</link>
		
		<!--********  RIGHT WHEEL ********-->
		<link name="right_wheel">
			<pose>0.275 -0.075 0.05 0 1.5707 6.283</pose>
			<inertial>
				<mass>1</mass>
				<pose>0 0 0.05 0 0 0</pose>
				<inertia>
					<ixx>0.5</ixx>
					<iyy>1.0</iyy>
					<izz>0.1</izz>
				</inertia>
			</inertial>
			<collision name="right_wheel_collision">
				<geometry>
					<cylinder>
						<radius>0.05</radius>
						<length>0.05</length>
					</cylinder>
				</geometry>
			</collision>
			<visual name="right_wheel_visual">
				<geometry>
					<cylinder>
						<radius>0.05</radius>
						<length>0.05</length>
					</cylinder>
				</geometry>
			</visual>
		</link>
		
		<!--********  LEFT WHEEL JOINT ********-->
		<joint type="revolute" name="left_wheel_hinge">
			<pose>0 0 -0.03 0 0 0</pose>
			<child>left_wheel</child>
			<parent>body</parent>
			<axis>
				<xyz>-1 0 0</xyz>
			</axis>
		</joint>

		<!--********  RIGHT WHEEL JOINT ********-->
		<joint type="revolute" name="right_wheel_hinge">
			<pose>0 0 0.03 0 0 0</pose>
			<child>right_wheel</child>
			<parent>body</parent>
			<axis>
				<xyz>-1 0 0</xyz>
			</axis>
		</joint>

		<!--********  APRIL TAG JOINT ********-->
		<joint name='april_tag_joint' type='fixed'>
			<parent>body</parent>
			<child>april_tag</child>
			<pose frame=''>0 0 0 0 -0 0</pose>
			<physics>
				<ode>
					<limit>
						<cfm>0</cfm>
						<erp>0.2</erp>
					</limit>
					<suspension>
						<cfm>0</cfm>
						<erp>0.2</erp>
					</suspension>
				</ode>
			</physics>
		</joint>


		<!--********  DIFFERENTIAL DRIVE PLUGIN ********-->
		<plugin name="differential_drive_controller" filename="libgazebo_ros_diff_drive.so">
			<alwaysOn>true</alwaysOn>
			<updateRate>60</updateRate>
			<leftJoint>left_wheel_hinge</leftJoint>
			<rightJoint>right_wheel_hinge</rightJoint>
			<wheelSeparation>0.5</wheelSeparation>
			<wheelDiameter>0.05</wheelDiameter>
			<torque>2</torque>
			<commandTopic>cmd_vel</commandTopic>
			<odometryTopic>odom</odometryTopic>
			<odometryFrame>odom</odometryFrame>
			<robotBaseFrame>body</robotBaseFrame>
			<legacyMode>false</legacyMode>
			<robotNamespace>shopper</robotNamespace>
		</plugin>
	</model>
</sdf>
